Workbook

Sheet Project Data
A1: Project Name | B1: ...
A3: Online team meeting | B3: https://fau.zoom-x.de/j/3913240515?pwd=TWo2NkZmaVZFWDVKckNKVzQyRG4zdz09
A5: Production system (if any) | B5: TBT
A6: Test system (if any) | B6: TBT
A8: GitHub repository | B8: https://github.com/amosproj/amos2025ws01-opensearch-load-tester
A9: GitHub feature board | B9: https://github.com/orgs/amosproj/projects/89/views/2
A10: GitHub imp-squared backlog | B10: https://github.com/orgs/amosproj/projects/93/views/1
A12: Team T-shirt (white) | B12: https://www.shirtinator.de/en/s/nasAq-u7RjO3FQ4BPPUSLw
A13: Team T-shirt (black) | B13: https://www.shirtinator.de/en/s/0VuwTYIwRviJfsV7ERwamA
A15: Additional materials | B15: ...
A17: Team maling list | B17: oss-amos-proj1@lists.fau.de

Sheet Project Team
A1: Last Name | B1: First Name | C1: GitHub User Name | D1: Email Address
A2: Lorenz | B2: Alexander | C2: Hydraneut | D2: alexander.lorenz@fau.de
A3: Buchner | B3: Lea | C3: LeaBuchner | D3: lea.buchner@fau.de
A4: Engelhard | B4: Dirk | C4: engelharddirk | D4: dirk.engelhard@fau.de
A5: Strachwitz | B5: Carlo | C5: Carlit0 | D5: carlostrachwitz@gmail.com
A6: Belz | B6: Sara | C6: SaraBelz | D6: sara.belz@fau.de
A7: Becker | B7: Eugen | C7: BeEugen | D7: eugen.becker@fau.de
A8: Hofmann | B8: Leo | C8: Leolingio | D8: leohof23@gmail.com
A9: Knecht | B9: Sebastian | C9: SeboKnt | D9: sebastian.knecht@fau.de

Sheet Role Assignments
C1: Product Owner
A2: # | B2: Meeting Day | C2: Review | D2: Planning | E2: Software Developer | F2: Release Manager | G2: Scrum Master | H2: Comment
A3: 1 | B3: 45945 | C3: both | D3: both | E3: Everyone else | F3: N/A | G3: Alexander Lorenz
A4: 2 | B4: =B3+7 -> 45952 | C4: Lea Buchner | D4: Dirk Engelhard | E4: Everyone else | F4: N/A | G4: Alexander Lorenz
A5: 3 | B5: =B4+7 -> 45959 | C5: Dirk Engelhard | D5: Lea Buchner | E5: Everyone else | F5: Carlo Strachwitz | G5: Alexander Lorenz
A6: 4 | B6: =B5+7 -> 45966 | C6: Lea Buchner | D6: Dirk Engelhard | E6: Everyone else | F6: Carlo Strachwitz | G6: Alexander Lorenz | H6: Build process review
A7: 5 | B7: =B6+7 -> 45973 | C7: Dirk Engelhard | D7: Lea Buchner | E7: Everyone else | F7: Leo Hofmann | G7: Alexander Lorenz
A8: 6 | B8: =B7+7 -> 45980 | C8: Lea Buchner | D8: Dirk Engelhard | E8: Everyone else | F8: Sara Belz | G8: Alexander Lorenz
A9: 7 | B9: =B8+7 -> 45987 | C9: Dirk Engelhard | D9: Lea Buchner | E9: Everyone else | F9: Sebastian Knecht | G9: Alexander Lorenz | H9: Mid-term due
A10: 8 | B10: =B9+7 -> 45994 | C10: Lea Buchner | D10: Dirk Engelhard | E10: Everyone else | F10: Eugen Becker | G10: Alexander Lorenz
A11: 9 | B11: =B10+7 -> 46001 | C11: Dirk Engelhard | D11: Lea Buchner | E11: Everyone else | F11: Eugen Becker | G11: Alexander Lorenz
A12: 10 | B12: =B11+7 -> 46008 | C12: Lea Buchner | D12: Dirk Engelhard | E12: Everyone else | F12: Leo Hofmann | G12: Alexander Lorenz | H12: Team Workshop
A13: 11 | B13: 46029 | C13: Dirk Engelhard | D13: Lea Buchner | E13: Everyone else | F13: Sara Belz | G13: Alexander Lorenz | H13: No class but team meeting
A14: 12 | B14: =B13+7 -> 46036 | C14: Lea Buchner | D14: Dirk Engelhard | E14: Everyone else | F14: Sebastian Knecht | G14: Alexander Lorenz
A15: 13 | B15: =B14+7 -> 46043 | C15: Dirk Engelhard | D15: Lea Buchner | E15: Everyone else | F15: Leo Hofmann | G15: Alexander Lorenz
A16: 14 | B16: =B15+7 -> 46050 | C16: Lea Buchner | D16: Dirk Engelhard | E16: Everyone else | F16: Sara Belz | G16: Alexander Lorenz
A17: 15 | B17: =B16+7 -> 46057 | C17: Dirk Engelhard | D17: Lea Buchner | E17: Everyone else | F17: Sebastian Knecht | G17: Alexander Lorenz | H17: Demo day!+retrospective
A19: Product owners, software developers, and Scurm Master are set and ideally don't change over time; the critical part is the Release Manager role you need to define here

Sheet Team Contract
A1: Goals | B1: achieve the project goal
B2: get inside into the scrum and agile process
B3: improve practical development skills
B4: create something worth using
A5: Meeting norms | B5: everybody should feel safe
B6: be punctual
B7: Absence from meetings should be (if possible) declared a day in advance
A8: Working norms | B8: open door policy (everybody should be allowed to do mistakes)
B9: maintaining good documentation
B10: Backlog items are assigned by the developers themselve before they work (outside the team meeting)
A11: Coordination norms | B11: every Backlog item has at least 1 deticated person (if work has already started on it)
B12: Contributers assigne them self to bakclog items
A13: Communication norms | B13: meetings take place in english unless stated otherwise
B14: stick to the topic of the channel
B15: We use discord as our primary method of communication
B16: we check discord at least once a day (and react if needed)
B17: We use Whatsapp for urgent communication (less than an hour)
A18: Consideration norms | B18: If you see something say something
B19: We decide with majority vote
B20: If we think we could help we extend it
A21: Cont. improvement norms | B21: constructive feedback is always welcome
B22: We jointly review the happiness index
A23: Rewards | B23: celebrate successes
B24: Appreciation and praise
A25: Sanctions | B25: apoligize sincerly
B26: and find a funny way to apoligize
A27: Signatures
A28: Scrum Master | B28: Alexander Lorenz
A29: Product owner | B29: Dirk Engelhard
A30: Product owner | B30: Lea Buchner
A31: Software developer | B31: Leo Hofmann
A32: Software developer | B32: Eugen Becker
A33: Software developer | B33: Sebastian Knecht
A34: Software developer | B34: Sara Belz
A35: Software developer | B35: Carlo Strachwitz

Sheet Product Goal
A1: Product Vision | B1: Project Mission
A3: The reason of existence of the envisioned product (beyond this project). | B3: The mission of this particular project (in the context of the product vision).

Sheet Product Glossary
A1: Term | B1: Definition

Sheet Sprint Goals
A1: Sprint # | B1: Sprint goal
A2: 1 | B2: None
A3: =A2+1 -> 2 | B3: None
A4: =A3+1 -> 3 | B4: None
A5: =A4+1 -> 4 | B5: Optional
A6: =A5+1 -> 5 | B6: Write your sprint goal here
A7: =A6+1 -> 6
A8: =A7+1 -> 7
A9: =A8+1 -> 8
A10: =A9+1 -> 9
A11: =A10+1 -> 10
A12: =A11+1 -> 11
A13: =A12+1 -> 12
A14: =A13+1 -> 13
A15: =A14+1 -> 14
A16: =A15+1 -> 15

Sheet Velocity Tracking
A1: Sprint # | B1: Story Points Realized
A2: 1
A3: =A2+1 -> 2
A4: =A3+1 -> 3
A5: =A4+1 -> 4
A6: =A5+1 -> 5
A7: =A6+1 -> 6
A8: =A7+1 -> 7
A9: =A8+1 -> 8
A10: =A9+1 -> 9
A11: =A10+1 -> 10
A12: =A11+1 -> 11
A13: =A12+1 -> 12
A14: =A13+1 -> 13
... A16: =A15+1 -> 15
B18: PLEASE CREATE THE VELOCITY CHART ON A NEW TAB USING THE DATA FROM THIS TAB

Sheet Velocity Chart
A1: Sprint # | B1: Story Points Realized
A2: 1
A3: =A2+1 -> 2
A4: =A3+1 -> 3
A5: =A4+1 -> 4
A6: =A5+1 -> 5
A7: =A6+1 -> 6
A8: =A7+1 -> 7
A9: =A8+1 -> 8
A10: =A9+1 -> 9
A11: =A10+1 -> 10
A12: =A11+1 -> 11
A13: =A12+1 -> 12
A14: =A13+1 -> 13
... A16: =A15+1 -> 15

Sheet Mid-Project Release plan
A1: Sprint | B1: Goal | C1: Feature Name | D1: Est. size | E1: Est. remaining | F1: Real size | G1: Real remaining
A3: Release
A5: Total | D5: =sum(D8:D13) -> 0 | E5: =D5 -> 0
A7: Sprints
E8: Estimated burn-down | G8: Real burn-down
A9: 1 | D9: =sum(D16:D21) -> 0 | E9: =$D$5 -> 0 | F9: =sum(F16:F21) -> 0 | G9: =$D$5 -> 0
A10: =A9+1 -> 2 | D10: =sum(D22:D27) -> 0 | E10: =E9-D9 -> 0 | F10: =sum(F22:F27) -> 0 | G10: =G9-F9 -> 0
A11: =A10+1 -> 3 | D11: =sum(D28:D33) -> 0 | E11: =E10-D10 -> 0 | F11: =sum(F28:F33) -> 0 | G11: =G10-F10 -> 0
A12: ... | E12: =E11-D11 -> 0 | G12: =G11-F11 -> 0
A14: Features
A16: =A9 -> 1 | B16: =B9
A22: =A10 -> 2 | B22: =B10
A28: =A11 -> 3 | B28: =B11
C33: PLEASE CREATE THE BURNDOWN CHART ON A NEW TAB USING THE DATA FROM THIS TAB

Sheet Final Project Release plan
A1: Sprint | B1: Goal | C1: Feature Name | D1: Est. size | E1: Est. remaining | F1: Real size | G1: Real remaining
A3: Release
A5: Total | D5: =sum(D8:D13) -> 0 | E5: =D5 -> 0
A7: Sprints
E8: Estimated burn-down | G8: Real burn-down
A9: 1 | D9: =sum(D16:D21) -> 0 | E9: =$D$5 -> 0 | F9: =sum(F16:F21) -> 0 | G9: =$D$5 -> 0
A10: =A9+1 -> 2 | D10: =sum(D22:D27) -> 0 | E10: =E9-D9 -> 0 | F10: =sum(F22:F27) -> 0 | G10: =G9-F9 -> 0
A11: =A10+1 -> 3 | D11: =sum(D28:D33) -> 0 | E11: =E10-D10 -> 0 | F11: =sum(F28:F33) -> 0 | G11: =G10-F10 -> 0
A12: ... | E12: =E11-D11 -> 0 | G12: =G11-F11 -> 0
A14: Features
A16: =A9 -> 1
A22: =A10 -> 2
A28: =A11 -> 3
C33: PLEASE CREATE THE BURNDOWN CHART ON A NEW TAB USING THE DATA FROM THIS TAB

Sheet Definition of Done
A1: # | B1: Feature Definition of Done | C1: Sprint Release Definition of Done | D1: Project Release Definition of Done

Sheet Documentation
A1: Type | B1: Link / reference

Sheet Bill of Materials
A1: # | B1: Context | C1: Name | D1: Version | E1: License | F1: Comment
A2: 1 | B2: environment | C2: Eclipse Temurin OpenJDK | D2: 25 (LTS) | E2: GPL-2.0 with Classpath Exception | F2: Java runtime used for building and running the application
A3: 2 | B3: environment | C3: Docker | D3: 28.5.1 | E3: Apache-2.0 | F3: Container environment for running OpenSearch and Load Tester services
A4: 3 | B4: tool | C4: Apache Maven | D4: 3.9.11 | E4: Apache-2.0 | F4: Build automation and dependency management tool
A5: 4 | B5: library | C5: spring-boot-starter | D5: 3.5.7 | E5: Apache-2.0 | F5: Entry point for Spring Boot dependency management
A6: 5 | B6: library | C6: spring-boot | D6: 3.5.7 | E6: Apache-2.0 | F6: Core framework providing auto-configuration and runtime support
A7: 6 | B7: library | C7: spring-context | D7: 6.2.12 | E7: Apache-2.0 | F7: Dependency injection and application context management
A8: 7 | B8: library | C8: spring-aop | D8: 6.2.12 | E8: Apache-2.0 | F8: Aspect-oriented programming support
A9: 8 | B9: library | C9: spring-beans | D9: 6.2.12 | E9: Apache-2.0 | F9: Bean creation and configuration framework
A10: 9 | B10: library | C10: spring-expression | D10: 6.2.12 | E10: Apache-2.0 | F10: Spring Expression Language (SpEL) processing
A11: 10 | B11: library | C11: spring-boot-autoconfigure | D11: 3.5.7 | E11: Apache-2.0 | F11: Automatically configures components based on classpath
A12: 11 | B12: library | C12: spring-boot-starter-logging | D12: 3.5.7 | E12: Apache-2.0 | F12: Default logging configuration using Logback
A13: 12 | B13: library | C13: logback-classic | D13: 1.5.20 | E13: EPL-1.0 | F13: Logging backend implementing SLF4J API
... A19: 18 | B19: library | C19: spring-jcl | D19: 6.2.12 | E19: Apache-2.0 | F19: Logging abstraction used internally by Spring
A20: 19 | B20: library | C20: snakeyaml | D20: 2.4 | E20: Apache-2.0 | F20: YAML parser for configuration files
A21: 20 | B21: library | C21: micrometer-core | D21: 1.15.5 | E21: Apache-2.0 | F21: Core metrics collection API
A22: 21 | B22: library | C22: micrometer-commons | D22: 1.15.5 | E22: Apache-2.0 | F22: Shared utilities for metrics instrumentation
A23: 22 | B23: library | C23: micrometer-observation | D23: 1.15.5 | E23: Apache-2.0 | F23: Captures timing and observation data for metrics
A24: 23 | B24: library | C24: HdrHistogram | D24: 2.2.2 | E24: CC0-1.0 | F24: High-resolution latency measurement library
A25: 24 | B25: library | C25: LatencyUtils | D25: 2.0.3 | E25: CC0-1.0 | F25: Helper utilities for latency tracking
A26: 25 | B26: library | C26: micrometer-registry-prometheus | D26: 1.15.5 | E26: Apache-2.0 | F26: Exposes Micrometer metrics to Prometheus
A27: 26 | B27: library | C27: prometheus-metrics-core | D27: 1.3.10 | E27: Apache-2.0 | F27: Core Prometheus metrics collection
A28: 27 | B28: library | C28: prometheus-metrics-model | D28: 1.3.10 | E28: Apache-2.0 | F28: Data model for Prometheus metrics
A29: 28 | B29: library | C29: prometheus-metrics-config | D29: 1.3.10 | E29: Apache-2.0 | F29: Configuration utilities for Prometheus metrics
A30: 29 | B30: library | C30: prometheus-metrics-tracer-common | D30: 1.3.10 | E30: Apache-2.0 | F30: Common tracing utilities for Prometheus exporters
A31: 30 | B31: library | C31: prometheus-metrics-exposition-formats | D31: 1.3.10 | E31: Apache-2.0 | F31: Serialization formats for Prometheus metrics
A32: 31 | B32: library | C32: prometheus-metrics-exposition-textformats | D32: 1.3.10 | E32: Apache-2.0 | F32: Text exposition format for Prometheus
... A62: 61 | B62: library | C62: joda-time | D62: 2.12.7 | E62: Apache-2.0 | F62: Date and time handling library
A63: 62 | B63: library | C63: t-digest | D63: 3.2 | E63: Apache-2.0 | F63: Statistical distribution estimation for percentiles
A64: 63 | B64: library | C64: log4j-api | D64: 2.24.3 | E64: Apache-2.0 | F64: Core Log4j 2 API
A65: 64 | B65: library | C65: log4j-jul | D65: 2.24.3 | E65: Apache-2.0 | F65: Bridge for Java Util Logging to Log4j
A66: 65 | B66: library | C66: jna | D66: 5.13.0 | E66: LGPL-2.1-or-later OR Apache-2.0 | F66: Java Native Access for system-level operations
A67: 66 | B67: library | C67: jzlib | D67: 1.1.3 | E67: BSD-4-Clause | F67: Java implementation of zlib compression
A68: 67 | B68: library | C68: reactor-core | D68: 3.7.12 | E68: Apache-2.0 | F68: Reactive programming support (Project Reactor)
A69: 68 | B69: library | C69: reactive-streams | D69: 1.0.4 | E69: MIT-0 | F69: Minimal reactive streams specification
A70: 69 | B70: library | C70: protobuf-java | D70: 3.22.3 | E70: BSD-3-Clause | F70: Google Protocol Buffers serialization
A71: 70 | B71: library | C71: opensearch-rest-client | D71: 2.16.0 | E71: Apache-2.0 | F71: Low-level REST client for OpenSearch
A72: 71 | B72: library | C72: httpclient | D72: 4.5.14 | E72: Apache-2.0 | F72: Apache HTTP client for network communication
A73: 72 | B73: library | C73: httpcore | D73: 4.4.16 | E73: Apache-2.0 | F73: Core transport components for Apache HTTP client
A74: 73 | B74: library | C74: httpasyncclient | D74: 4.1.5 | E74: Apache-2.0 | F74: Asynchronous HTTP client for non-blocking I/O
...

Sheet Planning Poker
A1: ='Project Team'!A1 -> Last Name | B1: ='Project Team'!B1 -> First Name | C1: Value
A2: ='Project Team'!A2 -> Lorenz | B2: ='Project Team'!B2 -> Alexander | C2: 5 | E2: =average(C2:C10) -> 5 | F2: =if(stdev(C2:C7) > 0,"NOK", "OK") -> OK
A3: ='Project Team'!A3 -> Buchner | B3: ='Project Team'!B3 -> Lea | C3: 5
A4: ='Project Team'!A4 -> Engelhard | B4: ='Project Team'!B4 -> Dirk
A5: ='Project Team'!A5 -> Strachwitz | B5: ='Project Team'!B5 -> Carlo
A6: ='Project Team'!A6 -> Belz | B6: ='Project Team'!B6 -> Sara | E6: 0 | F6: No size
A7: ='Project Team'!A7 -> Becker | B7: ='Project Team'!B7 -> Eugen | E7: 1 | F7: Trivial size
A8: ='Project Team'!A8 -> Hofmann | B8: ='Project Team'!B8 -> Leo | E8: 2 | F8: Small size
A9: ='Project Team'!A9 -> Knecht | B9: ='Project Team'!B9 -> Sebastian | E9: 3 | F9: Medium size
A10: ='Project Team'!A10 | B10: ='Project Team'!B10 | E10: 5 | F10: Large size
E11: 8 | F11: Very large size
E12: 13 | F12: Too large (size)
A14: How to play planning poker
A16: 1. Everyone type their number into their value field, don't hit return yet
A17: 2. Someone, perhaps a product owner, count down 3.. 2.. 1..
A18: 3. Then, everyone hit return to submit their value
